Workbook

Sheet DRE
A1: DRE Gerencial — Videl T&I Transportes
A2: Competencia: agosto/2026 · Regime: Simples Nacional (Anexo III) · Modelo asset-light · Valores mensais
B4: DEMONSTRACAO DO RESULTADO | C4: Quadro ATUAL (hoje, pre-decisao) | D4: Cenario APROVADO (decisoes 10/08) | E4: % AV (aprovado) | F4: Plano ORIGINAL (planilha recebida) | G4: Δ Aprovado vs Atual | H4: Δ Aprovado vs Original | I4: APROVADO Anual (x12)
B5: RECEITA BRUTA DE SERVICOS DE TRANSPORTE | C5: =Premissas!$C$5 -> 262400 | D5: =Premissas!$C$5 -> 262400 | E5: =IF(D$5=0,0,D5/D$5) -> 1 | F5: =Premissas!$C$5 -> 262400 | G5: =D5-C5 -> 0 | H5: =D5-F5 -> 0 | I5: =D5*12 -> 3148800
B6: (-) Simples Nacional — DAS | C6: =-C5*Premissas!$C$10 -> -39018.88 | D6: =-D5*Premissas!$C$10 -> -39018.88 | E6: =IF(D$5=0,0,D6/D$5) -> -0.1487 | F6: =-F5*Premissas!$C$10 -> -39018.88 | G6: =D6-C6 -> 0 | H6: =D6-F6 -> 0 | I6: =D6*12 -> -468226.56
B7: (=) RECEITA LIQUIDA | C7: =C5+C6 -> 223381.12 | D7: =D5+D6 -> 223381.12 | E7: =IF(D$5=0,0,D7/D$5) -> 0.8513 | F7: =F5+F6 -> 223381.12 | G7: =D7-C7 -> 0 | H7: =D7-F7 -> 0 | I7: =D7*12 -> 2680573.4
B8: CUSTO DOS SERVICOS PRESTADOS
B9: (-) Frete pago a terceiros / agregados | C9: =-C5*Premissas!$C$13 -> -160064 | D9: =-D5*Premissas!$C$13 -> -160064 | E9: =IF(D$5=0,0,D9/D$5) -> -0.61 | F9: =-F5*Premissas!$C$13 -> -160064 | G9: =D9-C9 -> 0 | H9: =D9-F9 -> 0 | I9: =D9*12 -> -1920768
B10: (-) Pedagio, GRIS e taxas de descarga | C10: =-C5*Premissas!$C$14 -> -7872 | D10: =-D5*Premissas!$C$14 -> -7872 | E10: =IF(D$5=0,0,D10/D$5) -> -0.03 | F10: =-F5*Premissas!$C$14 -> -7872 | G10: =D10-C10 -> 0 | H10: =D10-F10 -> 0 | I10: =D10*12 -> -94464
B11: (-) Seguro de carga (RCTR-C / RCF-DC) | C11: =-C5*Premissas!$C$15 -> -3148.8 | D11: =-D5*Premissas!$C$15 -> -3148.8 | E11: =IF(D$5=0,0,D11/D$5) -> -0.012 | F11: =-F5*Premissas!$C$15 -> -3148.8 | G11: =D11-C11 -> 0 | H11: =D11-F11 -> 0 | I11: =D11*12 -> -37785.6
B12: (=) CUSTO TOTAL DOS SERVICOS | C12: =SUM(C9:C11) -> -171084.8 | D12: =SUM(D9:D11) -> -171084.8 | E12: =IF(D$5=0,0,D12/D$5) -> -0.652 | F12: =SUM(F9:F11) -> -171084.8 | G12: =D12-C12 -> 0 | H12: =D12-F12 -> 0 | I12: =D12*12 -> -2053017.6
B13: (=) LUCRO BRUTO | C13: =C7+C12 -> 52296.32 | D13: =D7+D12 -> 52296.32 | E13: =IF(D$5=0,0,D13/D$5) -> 0.1993 | F13: =F7+F12 -> 52296.32 | G13: =D13-C13 -> 0 | H13: =D13-F13 -> 0 | I13: =D13*12 -> 627555.84
B14: DESPESAS OPERACIONAIS
B15: (-) Salarios e pro-labore | C15: =-'Folha Detalhada'!$B$21 -> -21011.4 | D15: =-'Folha Detalhada'!$C$21 -> -21911.4 | E15: =IF(D$5=0,0,D15/D$5) -> -0.083503811 | F15: =-'Folha Detalhada'!$D$21 -> -26811.4 | G15: =D15-C15 -> -900 | H15: =D15-F15 -> 4900 | I15: =D15*12 -> -262936.8
B16: (-) Encargos sobre folha CLT | C16: =-'Folha Detalhada'!$B$23 -> -4266.306 | D16: =-'Folha Detalhada'!$C$23 -> -4266.306 | E16: =IF(D$5=0,0,D16/D$5) -> -0.016258788 | F16: =-'Folha Detalhada'!$D$23 -> -4266.306 | G16: =D16-C16 -> 0 | H16: =D16-F16 -> 0 | I16: =D16*12 -> -51195.672
B17: (-) Vale-refeicao | C17: =-'Folha Detalhada'!$B$22 -> -3480 | D17: =-'Folha Detalhada'!$C$22 -> -3480 | E17: =IF(D$5=0,0,D17/D$5) -> -0.013262195 | F17: =-'Folha Detalhada'!$D$22 -> -3980 | G17: =D17-C17 -> 0 | H17: =D17-F17 -> 500 | I17: =D17*12 -> -41760
B18: (-) Comissoes comerciais | C18: =-C5*Premissas!$C$19 -> -2624 | D18: =-D5*Premissas!$C$19 -> -2624 | E18: =IF(D$5=0,0,D18/D$5) -> -0.01 | F18: =-F5*Premissas!$C$19 -> -2624 | G18: =D18-C18 -> 0 | H18: =D18-F18 -> 0 | I18: =D18*12 -> -31488
B19: (=) Total despesas com pessoal | C19: =SUM(C15:C18) -> -31381.706 | D19: =SUM(D15:D18) -> -32281.706 | E19: =IF(D$5=0,0,D19/D$5) -> -0.12302479 | F19: =SUM(F15:F18) -> -37681.706 | G19: =D19-C19 -> -900 | H19: =D19-F19 -> 5400 | I19: =D19*12 -> -387380.47
B20: (-) Despesas administrativas | C20: =-Premissas!$C$32 -> -16700 | D20: =-Premissas!$C$32 -> -16700 | E20: =IF(D$5=0,0,D20/D$5) -> -0.063643293 | F20: =-Premissas!$C$32 -> -16700 | G20: =D20-C20 -> 0 | H20: =D20-F20 -> 0 | I20: =D20*12 -> -200400
B21: (=) TOTAL DESPESAS OPERACIONAIS | C21: =C19+C20 -> -48081.706 | D21: =D19+D20 -> -48981.706 | E21: =IF(D$5=0,0,D21/D$5) -> -0.18666809 | F21: =F19+F20 -> -54381.706 | G21: =D21-C21 -> -900 | H21: =D21-F21 -> 5400 | I21: =D21*12 -> -587780.47
B22: (=) EBITDA | C22: =C13+C21 -> 4214.614 | D22: =D13+D21 -> 3314.614 | E22: =IF(D$5=0,0,D22/D$5) -> 0.012631913 | F22: =F13+F21 -> -2085.386 | G22: =D22-C22 -> -900 | H22: =D22-F22 -> 5400 | I22: =D22*12 -> 39775.368
B23: (-) Depreciacao e amortizacao | C23: =-Premissas!$C$35 -> 0 | D23: =-Premissas!$C$35 -> 0 | E23: =IF(D$5=0,0,D23/D$5) -> 0 | F23: =-Premissas!$C$35 -> 0 | G23: =D23-C23 -> 0 | H23: =D23-F23 -> 0 | I23: =D23*12 -> 0
B24: (=) EBIT (resultado operacional) | C24: =C22+C23 -> 4214.614 | D24: =D22+D23 -> 3314.614 | E24: =IF(D$5=0,0,D24/D$5) -> 0.012631913 | F24: =F22+F23 -> -2085.386 | G24: =D24-C24 -> -900 | H24: =D24-F24 -> 5400 | I24: =D24*12 -> 39775.368
B25: (+/-) Resultado financeiro | C25: =Premissas!$C$36 -> 0 | D25: =Premissas!$C$36 -> 0 | E25: =IF(D$5=0,0,D25/D$5) -> 0 | F25: =Premissas!$C$36 -> 0 | G25: =D25-C25 -> 0 | H25: =D25-F25 -> 0 | I25: =D25*12 -> 0
B26: (=) LUCRO LIQUIDO | C26: =C24+C25 -> 4214.614 | D26: =D24+D25 -> 3314.614 | E26: =IF(D$5=0,0,D26/D$5) -> 0.012631913 | F26: =F24+F25 -> -2085.386 | G26: =D26-C26 -> -900 | H26: =D26-F26 -> 5400 | I26: =D26*12 -> 39775.368
B28: INDICADORES
B29: Margem bruta (%) | C29: =IF(C5=0,0,C13/C5) -> 0.1993 | D29: =IF(D5=0,0,D13/D5) -> 0.1993 | F29: =IF(F5=0,0,F13/F5) -> 0.1993 | G29: =D29-C29 -> 0 | H29: =D29-F29 -> 0
B30: Margem EBITDA (%) | C30: =IF(C5=0,0,C22/C5) -> 0.016061791 | D30: =IF(D5=0,0,D22/D5) -> 0.012631913 | F30: =IF(F5=0,0,F22/F5) -> -0.0079473552 | G30: =D30-C30 -> -0.003429878 | H30: =D30-F30 -> 0.020579268
B31: Margem liquida (%) | C31: =IF(C5=0,0,C26/C5) -> 0.016061791 | D31: =IF(D5=0,0,D26/D5) -> 0.012631913 | F31: =IF(F5=0,0,F26/F5) -> -0.0079473552 | G31: =D31-C31 -> -0.003429878 | H31: =D31-F31 -> 0.020579268
B32: Custo de frete / receita (meta: 60% a 62%) | C32: =IF(C5=0,0,-C9/C5) -> 0.61 | D32: =IF(D5=0,0,-D9/D5) -> 0.61 | F32: =IF(F5=0,0,-F9/F5) -> 0.61 | G32: =D32-C32 -> 0 | H32: =D32-F32 -> 0 | I32: =IF(AND(D32>=0.6,D32<=0.62),"DENTRO DA META","FORA DA META") -> DENTRO DA META
B33: Folha total / receita (%) | C33: =IF(C5=0,0,-(C15+C16+C17)/C5) -> 0.10959492 | D33: =IF(D5=0,0,-(D15+D16+D17)/D5) -> 0.11302479 | F33: =IF(F5=0,0,-(F15+F16+F17)/F5) -> 0.13360406 | G33: =D33-C33 -> 0.003429878 | H33: =D33-F33 -> -0.020579268
B34: Receita de equilibrio (break-even, R$/mes) | C34: =IF(C29=0,0,(-C21-C23)/C29) -> 241252.92 | D34: =IF(D29=0,0,(-D21-D23)/D29) -> 245768.72 | F34: =IF(F29=0,0,(-F21-F23)/F29) -> 272863.55 | G34: =D34-C34 -> 4515.8053 | H34: =D34-F34 -> -27094.832 | I34: =IF(D5=0,0,D34/D5) -> 0.9366186
B35: Headcount | C35: ='Folha Detalhada'!$L$18 -> 8 | D35: ='Folha Detalhada'!$M$18 -> 9 | F35: ='Folha Detalhada'!$N$18 -> 12 | G35: =D35-C35 -> 1 | H35: =D35-F35 -> -3
B36: Custo total da folha (R$/mes) | C36: =-(C15+C16+C17) -> 28757.706 | D36: =-(D15+D16+D17) -> 29657.706 | F36: =-(F15+F16+F17) -> 35057.706 | G36: =D36-C36 -> 900 | H36: =D36-F36 -> -5400
B39: COMO LER — receita, custo de frete e despesas administrativas sao IDENTICOS nas tres colunas. A unica variavel e a folha.
B40: Coluna C (ATUAL): o time que esta na empresa hoje, 10/08/2026 — Giovani ainda dentro, nenhuma vaga preenchida.
B41: Coluna D (APROVADO): depois das decisoes de hoje — sai o Giovani, entram o Denner e 1 comercial para a matriz (R$ 1.500 + comissao).
B42: Coluna F (ORIGINAL): o plano da planilha recebida — todas as vagas preenchidas (Emilly + estagiario do Financeiro) e o Giovani renovado.
B44: AS DUAS LEITURAS QUE IMPORTAM:
B45: Coluna G (Aprovado vs Atual): o quadro aprovado custa R$ 900/mes A MAIS que o time de hoje. E investimento em comercial, nao corte.
...

Sheet Premissas
A1: Premissas da DRE — Videl T&I Transportes
A2: CNPJ 63.147.064/0001-30 · Base: agosto/2026 · Celulas AMARELAS = editar/confirmar com o financeiro
B4: RECEITA
B5: Receita bruta de servicos — mensal | C5: 262400 | D5: Run-rate jun+jul/26 do FreteBI: 61 embarques x ticket medio R$ 8.604 / 2 meses. Base FreteBI: R$ 576,5 mil e 67 embarques acumulados (abr-jul/26).
B6: Ticket medio por embarque | C6: 8604 | D6: R$ 576.500 / 67 embarques (FreteBI, acumulado abr-jul/26).
B7: Embarques/mes (implicito) | C7: =ROUND(Premissas!$C$5/Premissas!$C$6,0) -> 30 | D7: Calculado. Confere com jun=37 e jul=24 embarques.
B9: TRIBUTOS
B10: Aliquota efetiva Simples Nacional (DAS) | C10: 0.1487 | D10: ESTIMATIVA. Anexo III com troca de ISS por ICMS (LC 123/06 art. 18 §5-E, transporte intermunicipal/interestadual de cargas). 4a faixa, RBT12 ~R$ 3,1 mi: (3.150.000 x 16% - 35.640)/3.150.000 = 14,87%. CONFIRMAR o RBT12 real com a contabilidade — se for menor, a aliquota cai para 11,2%-13,5%.
B12: CUSTO DOS SERVICOS (modelo asset-light)
B13: % frete pago a terceiros / agregados | C13: 0.61 | D13: META DE OURO (CLAUDE.md): 60% a 62% do valor da operacao. Usado 61%, meio da meta.
B14: % pedagio / GRIS / taxas de descarga | C14: 0.03 | D14: ESTIMATIVA — confirmar media real por CT-e no Bsoft.
B15: % seguro de carga (RCTR-C / RCF-DC + ad valorem) | C15: 0.012 | D15: ESTIMATIVA — confirmar apolice Sompo/PAIVA.
B17: PESSOAL
B18: Encargos sobre folha CLT (%) | C18: 0.29 | D18: Simples Anexo III: a CPP ja esta dentro do DAS. Sobra FGTS 8% + 13o 8,33% + FGTS/13o 0,67% + ferias+1/3 11,11% + FGTS/ferias 0,89% = 29,0%. SE a empresa estiver no Lucro Presumido, trocar para 57,8% (+ INSS patronal 20% + RAT 3% + Terceiros 5,8%).
B19: Comissao comercial (% sobre receita bruta) | C19: 0.01 | D19: ESTIMATIVA. O comercial da matriz foi contratado a R$ 1.500 fixo + comissao. CONFIRMAR o percentual e a base (receita bruta x margem bruta).
B21: DESPESAS ADMINISTRATIVAS (mensal)
B22: Aluguel, condominio e IPTU | C22: 4500 | D22: ESTIMATIVA — substituir pelo realizado do razao contabil.
B23: Energia, agua, internet e telefonia | C23: 1800 | D23: ESTIMATIVA — substituir pelo realizado do razao contabil.
B24: Contabilidade | C24: 2500 | D24: ESTIMATIVA — substituir pelo realizado do razao contabil.
B25: Software e TI (Bsoft TMS, Google Workspace, FreteBras) | C25: 1500 | D25: ESTIMATIVA — substituir pelo realizado do razao contabil.
B26: Material de escritorio e limpeza | C26: 800 | D26: ESTIMATIVA — substituir pelo realizado do razao contabil.
B27: Viagens, combustivel e deslocamento comercial | C27: 2000 | D27: ESTIMATIVA — substituir pelo realizado do razao contabil.
B28: Marketing e prospeccao | C28: 1000 | D28: ESTIMATIVA — substituir pelo realizado do razao contabil.
B29: Tarifas bancarias | C29: 600 | D29: ESTIMATIVA — substituir pelo realizado do razao contabil.
B30: Juridico e consultorias | C30: 1000 | D30: ESTIMATIVA — substituir pelo realizado do razao contabil.
B31: Outras despesas administrativas | C31: 1000 | D31: ESTIMATIVA — substituir pelo realizado do razao contabil.
B32: TOTAL DESPESAS ADMINISTRATIVAS | C32: =SUM(C22:C31) -> 16700 | D32: ATENCAO: nenhum destes numeros veio de sistema. TODOS sao estimativa de mercado para transportadora asset-light deste porte. E a linha de menor confianca da DRE.
B34: ABAIXO DO EBITDA
B35: Depreciacao e amortizacao (mensal) | C35: 0 | D35: Modelo asset-light: a Videl nao tem frota propria (os 76 veiculos sao de terceiros/agregados). Preencher se houver imobilizado (moveis, TI, benfeitorias).
B36: Resultado financeiro liquido (mensal) | C36: 0 | D36: Negativo = despesa. Preencher com juros e antecipacao de recebiveis. Fonte sugerida: MCP do Banco PJ (extrato real).
B38: LEGENDA DE CORES
B39: Celula amarela + texto azul = input, edite aqui
B40: Texto preto = formula, nao editar
B41: Texto verde = link para outra aba

Sheet Folha Detalhada
A1: Folha de Pagamento — 3 cenarios
A2: Fonte: Dados_dos_Funcionarios.xlsx (aba Colaboradores). Colunas I, J e K: 1 = a pessoa entra no cenario, 0 = nao entra.
A4: Nome | B4: Cargo | C4: Contrato | D4: Decisao 10/08/2026 | E4: Salario / Pro-labore | F4: Vale-refeicao | G4: Encargos CLT | H4: Custo total mensal | I4: Quadro ATUAL (1/0) | J4: Cenario APROVADO (1/0) | K4: Plano ORIGINAL da planilha (1/0) | L4: Custo ATUAL | M4: Custo APROVADO | N4: Custo ORIGINAL
A5: Karolay Costa | B5: Coordenadora Administrativa | C5: CLT | D5: Mantida | E5: 4603.05 | F5: 0 | G5: =IF(1=1,E5*Premissas!$C$18,0) -> 1334.8845 | H5: =E5+F5+G5 -> 5937.9345 | I5: 1 | J5: 1 | K5: 1 | L5: =H5*I5 -> 5937.9345 | M5: =H5*J5 -> 5937.9345 | N5: =H5*K5 -> 5937.9345
A6: Gideoni Cantanhede Vieira | B6: Analista Comercial I | C6: CLT | D6: Mantido | E6: 3580.75 | F6: 660 | G6: =IF(1=1,E6*Premissas!$C$18,0) -> 1038.4175 | H6: =E6+F6+G6 -> 5279.1675 | I6: 1 | J6: 1 | K6: 1 | L6: =H6*I6 -> 5279.1675 | M6: =H6*J6 -> 5279.1675 | N6: =H6*K6 -> 5279.1675
A7: Hudson Fernando Melonio Mendes | B7: Assistente Comercial | C7: CLT | D7: Mantido | E7: 3000 | F7: 660 | G7: =IF(1=1,E7*Premissas!$C$18,0) -> 870 | H7: =E7+F7+G7 -> 4530 | I7: 1 | J7: 1 | K7: 1 | L7: =H7*I7 -> 4530 | M7: =H7*J7 -> 4530 | N7: =H7*K7 -> 4530
A8: Jose Adailton Santos | B8: Diretor Comercial/Adm | C8: PJ (sem CNPJ) | D8: Mantido | E8: 3000 | F8: 500 | G8: =IF(0=1,E8*Premissas!$C$18,0) -> 0 | H8: =E8+F8+G8 -> 3500 | I8: 1 | J8: 1 | K8: 1 | L8: =H8*I8 -> 3500 | M8: =H8*J8 -> 3500 | N8: =H8*K8 -> 3500
A9: Jhennifer Silva de Freitas | B9: Assistente Administrativo | C9: CLT | D9: Mantida | E9: 2027.6 | F9: 660 | G9: =IF(1=1,E9*Premissas!$C$18,0) -> 588.004 | H9: =E9+F9+G9 -> 3275.604 | I9: 1 | J9: 1 | K9: 1 | L9: =H9*I9 -> 3275.604 | M9: =H9*J9 -> 3275.604 | N9: =H9*K9 -> 3275.604
A10: Anderson da Silva Fernandes | B10: Comercial | C10: PJ 66.403.599/0001-12 | D10: Mantido | E10: 1800 | F10: 500 | G10: =IF(0=1,E10*Premissas!$C$18,0) -> 0 | H10: =E10+F10+G10 -> 2300 | I10: 1 | J10: 1 | K10: 1 | L10: =H10*I10 -> 2300 | M10: =H10*J10 -> 2300 | N10: =H10*K10 -> 2300
A11: Manoel Nunes Batista Neto | B11: Estagiario de TI | C11: CLT (verificar) | D11: Mantido | E11: 1500 | F11: 500 | G11: =IF(1=1,E11*Premissas!$C$18,0) -> 435 | H11: =E11+F11+G11 -> 2435 | I11: 1 | J11: 1 | K11: 1 | L11: =H11*I11 -> 2435 | M11: =H11*J11 -> 2435 | N11: =H11*K11 -> 2435
A12: Giovani Cantanhede Vieira | B12: Financeiro | C12: PJ 64.934.976/0001-14 | D12: NAO RENOVAR (venc. 31/07/2026) | E12: 1500 | F12: 0 | G12: =IF(0=1,E12*Premissas!$C$18,0) -> 0 | H12: =E12+F12+G12 -> 1500 | I12: 1 | J12: 0 | K12: 1 | L12: =H12*I12 -> 1500 | M12: =H12*J12 -> 0 | N12: =H12*K12 -> 1500
A13: Comercial - Matriz (1 vaga) | B13: Comercial | C13: PJ | D13: CONTRATAR — 1 vaga, R$ 1.500 + comissao | E13: 1500 | F13: 0 | G13: =IF(0=1,E13*Premissas!$C$18,0) -> 0 | H13: =E13+F13+G13 -> 1500 | I13: 0 | J13: 1 | K13: 1 | L13: =H13*I13 -> 0 | M13: =H13*J13 -> 1500 | N13: =H13*K13 -> 1500
A14: Denner | B14: Trainee | C14: PJ | D14: CONTRATAR | E14: 900 | F14: 0 | G14: =IF(0=1,E14*Premissas!$C$18,0) -> 0 | H14: =E14+F14+G14 -> 900 | I14: 0 | J14: 1 | K14: 1 | L14: =H14*I14 -> 0 | M14: =H14*J14 -> 900 | N14: =H14*K14 -> 900
A15: Emilly | B15: Comercial | C15: PJ | D15: NAO CONTRATAR (adiado) | E15: 1900 | F15: 500 | G15: =IF(0=1,E15*Premissas!$C$18,0) -> 0 | H15: =E15+F15+G15 -> 2400 | I15: 0 | J15: 0 | K15: 1 | L15: =H15*I15 -> 0 | M15: =H15*J15 -> 0 | N15: =H15*K15 -> 2400
A16: Estagiario - Financeiro | B16: Financeiro | C16: Estagio | D16: NAO CONTRATAR (adiado) | E16: 1500 | F16: 0 | G16: =IF(0=1,E16*Premissas!$C$18,0) -> 0 | H16: =E16+F16+G16 -> 1500 | I16: 0 | J16: 0 | K16: 1 | L16: =H16*I16 -> 0 | M16: =H16*J16 -> 0 | N16: =H16*K16 -> 1500
A17: TOTAL | L17: =SUM(L5:L16) -> 28757.706 | M17: =SUM(M5:M16) -> 29657.706 | N17: =SUM(N5:N16) -> 35057.706
A18: HEADCOUNT | L18: =SUM(I5:I16) -> 8 | M18: =SUM(J5:J16) -> 9 | N18: =SUM(K5:K16) -> 12
A20: QUEBRA POR RUBRICA | B20: Quadro ATUAL | C20: Cenario APROVADO | D20: Plano ORIGINAL
A21: Salarios e pro-labore | B21: =SUMPRODUCT(E5:E16,I5:I16) -> 21011.4 | C21: =SUMPRODUCT(E5:E16,J5:J16) -> 21911.4 | D21: =SUMPRODUCT(E5:E16,K5:K16) -> 26811.4
A22: Vale-refeicao | B22: =SUMPRODUCT(F5:F16,I5:I16) -> 3480 | C22: =SUMPRODUCT(F5:F16,J5:J16) -> 3480 | D22: =SUMPRODUCT(F5:F16,K5:K16) -> 3980
A23: Encargos CLT | B23: =SUMPRODUCT(G5:G16,I5:I16) -> 4266.306 | C23: =SUMPRODUCT(G5:G16,J5:J16) -> 4266.306 | D23: =SUMPRODUCT(G5:G16,K5:K16) -> 4266.306
A26: OS TRES CENARIOS:
A27: ATUAL = quem de fato esta na empresa hoje (10/08/2026), com o Giovani ainda dentro e nenhuma vaga preenchida.
A28: APROVADO = quadro depois das decisoes de hoje: sai o Giovani, entram o Denner e 1 comercial para a matriz.
A29: ORIGINAL = o plano como estava na planilha recebida: todas as vagas preenchidas (Emilly + estagiario do Financeiro) e o Giovani renovado.
A31: NOTAS E PENDENCIAS:
A32: 1) Karolay Costa esta sem vale-refeicao na planilha de origem. Se ela recebe VR, preencher F5 (impacto ~R$ 660/mes).
A33: 2) Manoel Nunes: o cargo e 'Estagiario de TI' mas o contrato esta marcado 'CLT'. Se for estagio (Lei 11.788) nao ha encargos — mudar o encargo dele para 0 economiza ~R$ 435/mes. Deixei como CLT (cenario conservador, custo maior).
A34: 3) Jose Adailton Santos esta como 'PJ-' sem CNPJ na planilha. Regularizar o cadastro.
A35: 4) DESLIGADOS recentes (aba 'desligados' da planilha de origem), ja fora de todos os cenarios: Enmerson Carlos Martins (Coordenador de Logistica, desligado 21/07/2026) e Marcos Paulo Hungria Oliveira (Assistente de Logistica, R$ 2.036,60, desligado 03/08/2026).
A36: 5) ATENCAO OPERACIONAL: com esses dois desligamentos a Videl ficou SEM headcount humano em Logistica. A operacao (67 embarques, 1.425 motoristas na base) passa a depender do Moita Rev1 e do comercial. E isso que sustenta a folha enxuta desta DRE.
A37: 6) A rescisao de Marcos Paulo (03/08/2026) e custo NAO-RECORRENTE de agosto/2026 e nao esta na DRE mensal. Lancar a parte.
A38: 7) Sem o Giovani e sem o estagiario, o Financeiro fica sem ninguem dedicado. Definir quem absorve (Karolay ou Jose Adailton).

Sheet Decisoes
A1: Registro de Decisoes de Quadro — 10/08/2026
A2: As duas ultimas colunas medem baselines DIFERENTES. Some cada uma na sua propria coluna, nunca as duas juntas.
A4: # | B4: Pessoa / Vaga | C4: Cargo | D4: Contrato | E4: Decisao | F4: Impacto na folha vs. quadro ATUAL | G4: Custo evitado vs. plano ORIGINAL | H4: Observacao
A5: 1 | B5: Giovani Cantanhede Vieira | C5: Financeiro | D5: PJ 64.934.976/0001-14 | E5: NAO RENOVAR | F5: -1500 | G5: -1500 | H5: Contrato PJ venceu em 31/07/2026, sem renovacao a partir de agosto. E a unica decisao que reduz a folha em relacao ao time de hoje. ATENCAO: definir quem absorve o Financeiro.
A6: 2 | B6: Denner | C6: Trainee | D6: PJ | E6: CONTRATAR | F6: 900 | G6: 0 | H6: Contratacao aprovada. Na planilha o cargo aparece como 'Trenier' — assumido Trainee. Ja estava previsto no plano original, entao nao muda nada em relacao a ele.
A7: 3 | B7: Comercial - Matriz | C7: Comercial | D7: PJ | E7: CONTRATAR (1 vaga) | F7: 1500 | G7: 0 | H7: Apenas 1 vaga, R$ 1.500 fixo + comissao. A comissao entra na DRE como % da receita (premissa editavel). Ja estava previsto no plano original.
A8: 4 | B8: Emilly | C8: Comercial | D8: PJ | E8: NAO CONTRATAR | F8: 0 | G8: -2400 | H8: Salario R$ 1.900 + VR R$ 500. Nunca entrou na folha, entao nao ha impacto vs. o time de hoje — e custo evitado. Vaga adiada, nao cancelada: reavaliar quando a receita passar de R$ 300 mil/mes.
A9: 5 | B9: Estagiario - Financeiro | C9: Financeiro | D9: Estagio | E9: NAO CONTRATAR | F9: 0 | G9: -1500 | H9: Vaga adiada. Somada a saida do Giovani, o Financeiro fica sem headcount dedicado — risco a mapear.
E10: EFEITO MENSAL | F10: =SUM(F5:F9) -> 900 | G10: =SUM(G5:G9) -> -5400 | H10: Coluna F confere com 'Δ Aprovado vs Atual' da DRE. Coluna G confere com 'Δ Aprovado vs Original' (com o sinal invertido: custo evitado).
E11: EFEITO ANUAL (x12) | F11: =F10*12 -> 10800 | G11: =G10*12 -> -64800
B13: POR QUE DUAS COLUNAS DE IMPACTO:
B14: A planilha recebida ja trazia o Denner, o comercial da matriz, a Emilly e o estagiario do Financeiro como 'A CONTRATAR', e o Giovani como ativo. Comparar contra ela mede o quanto o plano encolheu.
B15: Mas nenhuma dessas 4 vagas existe na folha de hoje. Comparar contra o time real mede o quanto vai sair do caixa a partir de agora.
B16: Somar as duas colunas juntas contaria a mesma decisao duas vezes.
